Workbook

Sheet BoQ Summary
A1: SLOPE STABILISATION AND LAND RECLAMATION OF RUNWAY 06
A2: KISUMU INTERNATIONAL AIRPORT
A3: CONTRACT NO: KAA/KIA/OT/0026/2025-2026
A4: BILL OF QUANTITIES
A5: Summary
A6: Item no. | B6: Description | C6: Appraised Amount
A7: 1 | B7: GENERAL: Office administration and overheads/Preliminaries | C7: ='BoQ 1; Preliminaries'!F21 -> 18377000
A8: 4 | B8: SITE CLEARANCE | C8: ='BoQ 4; Site Clearance'!F13 -> 8623050
A9: 5 | B9: EARTHWORKS | C9: ='BoQ 5; Earthworks'!F14 -> 215418000
A10: 7 | B10: EXCAVATION AND FILLING FOR STRUCTURES | C10: ='BoQ 7; Excavation'!F13 -> 19135700
A11: 10 | B11: GRAVEL WEARING COURSE | C11: ='BoQ 10&20; Gravel & RDfurniture'!F9 -> 5030300
A12: 20 | B12: ROAD FURNITURE | C12: ='BoQ 10&20; Gravel & RDfurniture'!F28 -> 12633000
A13: 22 | B13: DAYWORKS | C13: ='BoQ 22; Dayworks'!F153 -> 5467077
A14: A | B14: Sub Total 1 | C14: =SUM(C7:C13) -> 284684127
A16: B | B16: Add 5% of Sub-Total 1 of Bills as Provisional Sum for contigencies to be expended in the whole or part or deleted by the Engineer | C16: =0.05*C14 -> 14234206
A18: C | B18: Sub Total 2 | C18: =C14+C16 -> 2.9891833e+08
A20: D | B20: Add 16% of Sub-Total 2 for Value Added Tax (VAT) | C20: =0.16*C18 -> 47826933
A22: E | B22: Sub Total 3 | C22: =C18+C20 -> 3.4674527e+08
A24: F | B24: Add 0.03% of E for Public Procurement Capacity Building Levy (PPCBL) | C24: =0.0003*C22 -> 104023.58
B26: Grand total carried to page on the tender | C26: =C22+C24 -> 3.4684929e+08

Sheet BoQ 1; Preliminaries
A1: SLOPE STABILISATION AND LAND RECLAMATION OF RUNWAY 06
A2: KISUMU INTERNATIONAL AIRPORT
A3: CONTRACT NO: KAA/KIA/OT/0026/2025-2026
A4: BILL OF QUANTITIES
A5: Bill No. 1 | B5: PRELIMINARIES
A6: Item No | B6: Description | C6: Units | D6: Quantity | E6: Rate (Ksh) | F6: Amount (Ksh)
A7: 1.01 | B7: Maintain a furnished Engineer's Representative's 40ft Containerized office to be provided by the Client or as instructed by the Engineer for use during the duration of the Contract. Maintenance shall include provision of electricity, water and starlink speed internet. Ownership shall revert back to the Employer. | C7: L Sum | D7: 1 | E7: 2000000 | F7: =D7*E7 -> 2000000
A8: 1.02 | B8: Provide an ablution block as per the drawing. | C8: Item | D8: 1 | E8: 1500000 | F8: =D8*E8 -> 1500000
A9: 1.03 | B9: Provide and install reinforced (weight of steel 80kg/m3-120kg/m3) concrete Septic Tank of 25,000 ltrs capacity | C9: Item | D9: 1 | E9: 1800000 | F9: =D9*E9 -> 1800000
A10: 1.01 | B10: Allow a prime cost Sum of Ksh 4,000,000 for Engineer's Miscellaneous account. | C10: Item | D10: 1 | E10: 4000000 | F10: =E10*D10 -> 4000000
A11: 1.02 | B11: Include percentage of P.C sum in item 1.01 for Contractor's overheads and profit. | C11: Item | D11: 1 | E11: =0.15*E10 -> 600000 | F11: =D11*E11 -> 600000
A12: 1.03 | B12: Hiring boat services for water Survey Works | C12: Per Day | D12: 30 | E12: 40000 | F12: =D12*E12 -> 1200000
A13: 1.04 | B13: Preparation of detailed Construction/Shop drawings as instructed by the Engineer | C13: L Sum | D13: 1 | E13: 750000 | F13: =D13*E13 -> 750000
A14: 1.05 | B14: Provide with driver, fuel, service and maintain, insure 1No. New 4WD Double Cab pickup vehicle recorded mileage below 20,000, diesel engine capacity 2800-3000 cc fitted with front bull bars, lockable water/dust proof vehicle colour matching fibre material carrier cover integrated with hinges and carrier lighting for exclusive use of the Engineer inclusive of the first 5,000 km per vehicle month to Engineer’s approval. Vehicle to revert back to the Contractor. | C14: Veh. Month | D14: 14 | E14: 250000 | F14: =D14*E14 -> 3500000
A15: 1.06 | B15: Extra over item 1.05 for mileage over 5,000 km per vehicle month inclusive of all fuels, lubricants, servicing and maintenance, insurances and driver | C15: KM | D15: 7200 | E15: 35 | F15: =D15*E15 -> 252000
A16: 1.07 | B16: Provide automatic level machine complete with levelling staff and levelling bubble for exclusive use by the Engineer’s representative for the entire duration of the contract as per special specifications | C16: Month | D16: 14 | E16: 10000 | F16: =D16*E16 -> 140000
A17: 1.08 | B17: Provide project signboard being 1200 mm × 600 mm Gauge 14 (1.9 mm thick) mild steel plate welded onto 50 mm × 50 mm × 3 mm square hollow sections frame, 2.5 m frame with 0.5 m fixed below ground and painted approved colours for the duration of the project including the defects liability period | C17: No. | D17: 1 | E17: 35000 | F17: =D17*E17 -> 35000
A18: 1.09 | B18: Provide Airtime worth KES 100,000 per month for Supervision Staff as instructed by the Engineer | C18: Months | D18: 14 | E18: 100000 | F18: =D18*E18 -> 1400000
A19: 1.1 | B19: Provide for removing the stands, disconnection and reconnection of Final Approach Lights as instructed by the Engineer | C19: Lump Sum | D19: 1 | E19: 1200000 | F19: =D19*E19 -> 1200000
B21: Grand total carried to page on the tender | F21: =SUM(F7:F19) -> 18377000

Sheet BoQ 4; Site Clearance
A1: SLOPE STABILISATION AND LAND RECLAMATION OF RUNWAY 06
A2: KISUMU INTERNATIONAL AIRPORT
A3: CONTRACT NO: KAA/KIA/OT/0026/2025-2026
A4: BILL OF QUANTITIES
A5: Bill No. 4 | B5: SITE CLEARANCE AND TOP SOIL STRIPPING
A6: Item No | B6: Description | C6: Units | D6: Quantity | E6: Rate (Ksh) | F6: Amount (Ksh)
A7: 4.01 | B7: Clear site including removal of hedges, bushes, trees including uprooting of bushes and other vegetation and objectionable materials in accordance with the specifications | C7: Ha | D7: 5 | E7: 1060000 | F7: =D7*E7 -> 5300000
A8: 4.02 | B8: Removal of topsoil to spoil. Depth not exceeding 200 mm | C8: m³ | D8: 8400 | E8: 350 | F8: =D8*E8 -> 2940000
A9: 4.03 | B9: Demolition to spoiling of concrete structures | C9: m³ | D9: 10 | E9: 1305 | F9: =D9*E9 -> 13050
A10: 4.04 | B10: Removal of barbed wire or chain link fence and storing to a designated location as instructed by the Engineer | C10: m | D10: 500 | E10: 180 | F10: =D10*E10 -> 90000
A11: 4.05 | B11: Relocation of existing fence as instructed by the Engineer | C11: m | D11: 100 | E11: 2800 | F11: =D11*E11 -> 280000
B13: Grand total carried to page on the tender | F13: =SUM(F7:F11) -> 8623050

Sheet BoQ 5; Earthworks
A1: SLOPE STABILISATION AND LAND RECLAMATION OF RUNWAY 06
A2: KISUMU INTERNATIONAL AIRPORT
A3: CONTRACT NO: KAA/KIA/OT/0026/2025-2026
A4: BILL OF QUANTITIES
A5: Bill No. 5 | B5: EARTHWORKS
A6: Item No | B6: Description | C6: Units | D6: Quantity | E6: Rate (Ksh) | F6: Amount (Ksh)
A7: 5.01 | B7: Provide, lay and compact soft material in layers not exceeding 150 mm in fill as directed by the Engineer | C7: m³ | D7: 21000 | E7: 1412 | F7: =D7*E7 -> 29652000
A8: 5.02 | B8: Extra over item 5.01 for compaction of top 300 mm to 100% MDD (AASHTO T99) | C8: m³ | D8: 12600 | E8: 550 | F8: =D8*E8 -> 6930000
A9: 5.03 | B9: Spoil in soft material | C9: m³ | D9: 21000 | E9: 296 | F9: =D9*E9 -> 6216000
A10: 5.04 | B10: Provide, lay and compact in 200 mm layers approved rockfill as directed by the Engineer | C10: m³ | D10: 21000 | E10: 4180 | F10: =D10*E10 -> 87780000
A11: 5.05 | B11: 50 mm top soiling to specification | C11: m³ | D11: 42000 | E11: 1500 | F11: =D11*E11 -> 63000000
A12: 5.06 | B12: Grassing to specifications | C12: m² | D12: 42000 | E12: 520 | F12: =D12*E12 -> 21840000
B14: Grand total carried to page on the tender | F14: =SUM(F7:F12) -> 215418000

Sheet BoQ 7; Excavation
A1: SLOPE STABILISATION AND LAND RECLAMATION OF RUNWAY 06
A2: KISUMU INTERNATIONAL AIRPORT
A3: CONTRACT NO: KAA/KIA/OT/0026/2025-2026
A4: BILL OF QUANTITIES
A5: Bill No. 7 | B5: EXCAVATION AND FILLING FOR STRUCTURES
A6: Item No | B6: Description | C6: Units | D6: Quantity | E6: Rate (Ksh) | F6: Amount (Ksh)
A7: 7.01 | B7: Excavate for structures in soft material | C7: m³ | D7: 2200 | E7: 296 | F7: =D7*E7 -> 651200
A8: 7.02 | B8: Extra over item 7.01 for excavation in hard material | C8: m³ | D8: 1100 | E8: 295 | F8: =D8*E8 -> 324500
A9: 7.03 | B9: Provide and place 2 m × 1 m triple twisted wire 2.6 mm thick galvanised wire gabion mesh boxes | C9: m² | D9: 8600 | E9: 574 | F9: =D9*E9 -> 4936400
A10: 7.04 | B10: Provide and place rock fill to gabion mesh boxes | C10: m³ | D10: 1600 | E10: 7766 | F10: =D10*E10 -> 12425600
A11: 7.05 | B11: Provide and place filter fabric (300 g/m²) under or behind gabions | C11: m² | D11: 2100 | E11: 380 | F11: =D11*E11 -> 798000
B13: Grand total carried to page on the tender | F13: =SUM(F7:F11) -> 19135700

Sheet BoQ 10&20; Gravel & RDfurniture
A1: SLOPE STABILISATION AND LAND RECLAMATION OF RUNWAY 06
A2: KISUMU INTERNATIONAL AIRPORT
A3: CONTRACT NO: KAA/KIA/OT/0026/2025-2026
A4: BILL OF QUANTITIES
A5: Bill No. 10 | B5: GRAVEL WEARING COURSE (PATROL ROAD)
A6: Item No | B6: Description | C6: Units | D6: Quantity | E6: Rate (Ksh) | F6: Amount (Ksh)
A7: 10.01 | B7: Gravel wearing course to specifications | C7: m³ | D7: 1700 | E7: 2959 | F7: =D7*E7 -> 5030300
B9: Grand total carried to page on the tender | F9: =SUM(F7:F7) -> 5030300
A11: Bill No. 20 | B11: ROAD FURNITURE
A12: Item No | B12: Description | C12: Units | D12: Quantity | E12: Rate (Ksh) | F12: Amount (Ksh)
A13: 20.01 | B13: Excavate holes for fencing posts footing not exceeding 1.50 m deep, average 1.0 m deep in hard and soft material; ram base to receive Class 20 concrete bases; include carting away | C13: m³ | D13: 200 | E13: 450 | F13: =D13*E13 -> 90000
A14: 20.02 | B14: Ditto but for chain-link anchoring posts | C14: m³ | D14: 100 | E14: 450 | F14: =D14*E14 -> 45000
A15: 20.03 | B15: Mass concrete; Class 20 in footings | C15: m³ | D15: 200 | E15: 12000 | F15: =D15*E15 -> 2400000
A16: 20.04 | B16: Ditto but for chain-link anchoring posts | C16: m³ | D16: 100 | E16: 12000 | F16: =D16*E16 -> 1200000
A17: 20.05 | B17: Supply and install precast reinforced intermediate posts size 150×150 mm overall height 3500 mm inclusive of cranked top 475 mm long as per detailed drawing including labour for 6 mm diameter holes and bolts and 8 mm galvanized mild steel bars with 12.5 SWG stirrups at 350 mm c/c as per detailed drawing to Engineer’s approval and satisfaction | C17: No. | D17: 190 | E17: 5500 | F17: =D17*E17 -> 1045000
A18: 20.06 | B18: Ditto but precast reinforced straining posts size 150×150 mm overall height 3500 mm inclusive of cranked top 475 mm long including provision to receive struts to detail drawing | C18: No. | D18: 40 | E18: 6000 | F18: =D18*E18 -> 240000
A19: 20.07 | B19: 150 × 80 mm precast reinforced concrete struts to detail anchor on concrete base and straining posts at approved level and 45° to the horizontal | C19: No. | D19: 70 | E19: 2500 | F19: =D19*E19 -> 175000
A20: 20.08 | B20: Supply and fix 2.4 m high galvanized chain-link (gauge 9, 3.5 mm thick wire), 50×50 mm mesh onto precast concrete posts; fastening with 5 No. lines of galvanized wire threaded through mesh and hook bolts | C20: Lm | D20: 550 | E20: 3500 | F20: =D20*E20 -> 1925000
A21: 20.09 | B21: High tensile galvanized barbed wire 12½ G (2.5 mm diameter) threaded through posts secured by galvanized binding wire | C21: Lm | D21: 1700 | E21: 55 | F21: =D21*E21 -> 93500
A22: 20.1 | B22: High tensile galvanized straining wire 9 Gauge threaded through concrete posts including hook bolts | C22: Lm | D22: 2200 | E22: 80 | F22: =D22*E22 -> 176000
A23: 20.11 | B23: Excavate 150 mm × 300 mm for ground beam | C23: m³ | D23: 60 | E23: 350 | F23: =D23*E23 -> 21000
A24: 20.12 | B24: Mass concrete; Class 20 in ground beam | C24: m³ | D24: 60 | E24: 12000 | F24: =D24*E24 -> 720000
... A26: 20.14 | B26: Supply and install 450mm diameter galvanized steel spiral razor 2.5mm diameter, high tensile blade/strip 0.55mm, BTC-18 hot dipped galvanized surface treatment fastened along the fence, three lines at the base. | C26: Lm | D26: 550 | E26: 550 | F26: =D26*E26 -> 302500
B28: Grand total carried to page on the tender | F28: =SUM(F13:F26) -> 12633000

Sheet BoQ 22; Dayworks
A1: SLOPE STABILISATION AND LAND RECLAMATION OF RUNWAY 06
A2: KISUMU INTERNATIONAL AIRPORT
A3: CONTRACT NO: KAA/KIA/OT/0026/2025-2026
A4: BILL OF QUANTITIES
A5: Bill No. 22 | B5: DAYWORKS
A6: Item No | B6: Description | C6: Units | D6: Quantity | E6: Rate (Ksh) | F6: Amount (Ksh)
B7: Plant
B8: Crawler Dozers with Dozer and Hydraulic Ripper Attachments:
B9: 100 - 135 kW rated flywheel power | C9: hr | D9: 10 | E9: 7440 | F9: =D9*E9 -> 74400
B10: 136 - 185 kW rated flywheel power | C10: hr | D10: 10 | E10: 8930 | F10: =D10*E10 -> 89300
B11: 186-250 kw rated flywheel power | C11: hr | D11: 10 | E11: 11000 | F11: =D11*E11 -> 110000
B12: Motorized rubber tyred single engine scrapers
B13: up to 16m3 heaped capacity | C13: hr | D13: 10 | E13: 9000 | F13: =D13*E13 -> 90000
B14: 17 - 26m3 heaped capacity | C14: hr | D14: 10 | E14: 12000 | F14: =D14*E14 -> 120000
B15: Motorized rubber tyred twin engine scrapers
B16: up to 16m3 heaped capacity | C16: hr | D16: 10 | E16: 12000 | F16: =D16*E16 -> 120000
B17: 17 - 26m3 heaped capacity | C17: hr | D17: 10 | E17: 15000 | F17: =D17*E17 -> 150000
B18: Motor graders complete with Hydraulic Ripper or scarifier
B19: 80-110 kw rated flywheel power | C19: hr | D19: 10 | E19: 5600 | F19: =D19*E19 -> 56000
B20: 111-120 kw rated flywheel power | C20: hr | D20: 10 | E20: 6000 | F20: =D20*E20 -> 60000
B21: 121-160 kw rated flywheel power | C21: hr | D21: 10 | E21: 6500 | F21: =D21*E21 -> 65000
B22: Rollers - Towed Vibratory Including Tractor:
B23: 6.5 - 8.8 t unballasted wt. | C23: hr | D23: 10 | E23: 3200 | F23: =D23*E23 -> 32000
B24: 8.9 - 11.7 t unballasted wt. | C24: hr | D24: 10 | E24: 4129 | F24: =D24*E24 -> 41290
B25: Rollers - Road Deadweight (steel three wheel):
B26: 6.1 - 8.5 t unballasted wt. | C26: hr | D26: 10 | E26: 3000 | F26: =D26*E26 -> 30000
B27: Rollers - Rubber Tyred Self-Propelled:
B28: up to 1.0 t per wheel | C28: hr | D28: 10 | E28: 3254 | F28: =D28*E28 -> 32540
B29: Rollers - Vibratory Single Roll Rubber Tyred
B30: 8.3 - 10.5 t unballasted wt. | C30: hr | D30: 10 | E30: 4129 | F30: =D30*E30 -> 41290
B31: Rollers - Vibratory Pedestrian Operated Twin Roller:
B32: 651 kg - 1.3 t un-ballasted weight | C32: hr | D32: 10 | E32: 1532 | F32: =D32*E32 -> 15320
B33: Vibrating Plate Compactor:
B34: 114 - 200 kg operating weight. | C34: hr | D34: 10 | E34: 300 | F34: =D34*E34 -> 3000
B35: Compressors - Rated by Normal Delivery of Free Air per min at 7 kg per cm² Complete with all Tools, Hoses, Steel etc.
B36: 6.0 - 7.4m³/min | C36: hr | D36: 10 | E36: 1956 | F36: =D36*E36 -> 19560
B37: 7.5 - 9.7m³/min | C37: hr | D37: 10 | E37: 2600 | F37: =D37*E37 -> 26000
B38: 9.8-25.5m3/min | C38: hr | D38: 10 | E38: 3500 | F38: =D38*E38 -> 35000
B39: Cranes - Mobile Rubber Tyred Rough Terrain Type:
B40: 23.0 - 40.0 t max working load | C40: hr | D40: 10 | E40: 12000 | F40: =D40*E40 -> 120000
...

Sheet Engineers office
A1: SLOPE STABILISATION AND LAND RECLAMATION OF RUNWAY 06
A2: KISUMU INTERNATIONAL AIRPORT
A3: CONTRACT NO: KAA/KIA/OT/0026/2025-2026
A4: BILL OF QUANTITIES
A5: Bill No. | B5: FURNITURE AND EQUIPMENT FOR THE ENGINEER OFFICE
A6: Item No | B6: Description | C6: Units | D6: Quantity | E6: Rate (Ksh) | F6: Amount (Ksh)
A7: 1 | B7: Executive office desk with side returns with open shelves and drawer, leatherette writing pad, equipped with grommets for wire management (minimum surface area 2.8 m) | C7: No. | D7: 1 | E7: 85000 | F7: =D7*E7 -> 85000
A8: 2 | B8: High back executive swivel ergonomic leather chair adjustable height | C8: No. | D8: 2 | E8: 28000 | F8: =D8*E8 -> 56000
A9: 3 | B9: 1.4 m long office desk, with lockable drawers | C9: No. | D9: 3 | E9: 30000 | F9: =D9*E9 -> 90000
A10: 4 | B10: Visitor’s seats with armrest | C10: No. | D10: 4 | E10: 12000 | F10: =D10*E10 -> 48000
A11: 5 | B11: Typist table complete with a chair | C11: No. | D11: 1 | E11: 25000 | F11: =D11*E11 -> 25000
A12: 6 | B12: 4-drawer lockable steel fire proof filing cabinets with combination locks | C12: No. | D12: 2 | E12: 85000 | F12: =D12*E12 -> 170000
A13: 7 | B13: 3 m × 3 levels wooden lockable cabinets with high swing glass doors and lower level in wooden doors | C13: No. | D13: 2 | E13: 95000 | F13: =D13*E13 -> 190000
A14: 8 | B14: 4 Way detachable workstation office desk 2.4 m × 2.4 m with lockable drawers and screens | C14: No. | D14: 4 | E14: 150000 | F14: =D14*E14 -> 600000
A15: 9 | B15: Conference table for 10 sitting positions minimum size 1.8 m × 4.8 m with power and data sockets | C15: No. | D15: 1 | E15: 120000 | F15: =D15*E15 -> 120000
A16: 10 | B16: High back executive swivel orthopedic chair adjustable height | C16: No. | D16: 6 | E16: 28000 | F16: =D16*E16 -> 168000
A17: 11 | B17: Lockable cupboards | C17: No. | D17: 1 | E17: 45000 | F17: =D17*E17 -> 45000
A18: 12 | B18: Soft board for wall notices, drawings & other civil works 1.2 m × 0.9 m | C18: No. | D18: 2 | E18: 6000 | F18: =D18*E18 -> 12000
... A30: 24 | B30: Unlimited 40 Mbps or more wireless high speed Internet for the duration of the Contract | C30: No. | D30: 1 | E30: 120000 | F30: =D30*E30 -> 120000
F31: =SUM(F7:F30) -> 3189100

Sheet Engineers lab equipment
A1: SLOPE STABILISATION AND LAND RECLAMATION OF RUNWAY 06
A2: KISUMU INTERNATIONAL AIRPORT
A3: CONTRACT NO: KAA/KIA/OT/0026/2025-2026
A4: BILL OF QUANTITIES
A5: Bill No. | B5: FURNITURE AND EQUIPMENT FOR THE ENGINEER LABORATORY
A6: Item No | B6: Description | C6: Units | D6: Quantity | E6: Rate (Ksh) | F6: Amount (Ksh)
A7: 1 | B7: Desk 2.2 × 0.9 m with 1 chest of drawers | C7: No. | D7: 1 | E7: 35000 | F7: =D7*E7 -> 35000
A8: 2 | B8: Office chairs, standard | C8: No. | D8: 3 | E8: 8000 | F8: =D8*E8 -> 24000
A9: 3 | B9: 4-drawer steel lockable filing cabinet | C9: No. | D9: 1 | E9: 28000 | F9: =D9*E9 -> 28000
A10: 4 | B10: Electronic scientific calculator, 12 figures | C10: No. | D10: 2 | E10: 3000 | F10: =D10*E10 -> 6000
A11: 5 | B11: Fire extinguisher, 10 litre capacity, CO₂ type | C11: No. | D11: 2 | E11: 12000 | F11: =D11*E11 -> 24000
A12: 6 | B12: Steel filing cabinet, 4 drawers, lockable | C12: No. | D12: 1 | E12: 28000 | F12: =D12*E12 -> 28000
A13: 7 | B13: Book shelf, 3 shelves, 1.2 m long | C13: No. | D13: 2 | E13: 20000 | F13: =D13*E13 -> 40000
A14: 8 | B14: First aid kit | C14: No. | D14: 1 | E14: 5000 | F14: =D14*E14 -> 5000
A15: 9 | B15: Compaction mould complete with base plate and extension collar | C15: No. | D15: 2 | E15: 18000 | F15: =D15*E15 -> 36000
A16: 10 | B16: 2.5 kg compaction hammer | C16: No. | D16: 2 | E16: 6000 | F16: =D16*E16 -> 12000
A17: 11 | B17: 4.535 kg compaction rammer | C17: No. | D17: 2 | E17: 8000 | F17: =D17*E17 -> 16000
A18: 12 | B18: Straight edge 300 mm with handles | C18: No. | D18: 3 | E18: 2000 | F18: =D18*E18 -> 6000
... A30: 24 | B30: Glass plate | C30: No. | D30: 2 | E30: 600 | F30: =D30*E30 -> 1200
B31: Density (Sand Replacement Method BS 1377)
A32: 25 | B32: Metal container (450 mm dia) | C32: No. | D32: 4 | E32: 4000 | F32: =D32*E32 -> 16000
A33: 26 | B33: Stainless steel tray 305 mm dia | C33: No. | D33: 4 | E33: 2000 | F33: =D33*E33 -> 8000
A34: 27 | B34: Metal tray with 150 mm hole in centre | C34: No. | D34: 3 | E34: 2500 | F34: =D34*E34 -> 7500
A35: 28 | B35: Metal tray with 200 mm hole in centre | C35: No. | D35: 3 | E35: 3000 | F35: =D35*E35 -> 9000
A36: 29 | B36: Steel pegs for tray fixing | C36: No. | D36: 20 | E36: 250 | F36: =D36*E36 -> 5000
A37: 30 | B37: Sand pouring cylinder 150 mm dia | C37: No. | D37: 2 | E37: 38000 | F37: =D37*E37 -> 76000
A38: 31 | B38: Sand pouring cylinder 215 mm dia | C38: No. | D38: 2 | E38: 48000 | F38: =D38*E38 -> 96000
A39: 32 | B39: Cold steel chisel 20 × 300 mm | C39: No. | D39: 6 | E39: 1500 | F39: =D39*E39 -> 9000
A40: 33 | B40: Cold steel chisel 10 × 250 mm | C40: No. | D40: 6 | E40: 1200 | F40: =D40*E40 -> 7200
A41: 34 | B41: Mason hammers and rubber mallet set | C41: Set | D41: 3 | E41: 3500 | F41: =D41*E41 -> 10500
A42: 35 | B42: Scoop for removing excavated material | C42: No. | D42: 10 | E42: 800 | F42: =D42*E42 -> 8000
A43: 36 | B43: 100 mm brush soft | C43: No. | D43: 4 | E43: 300 | F43: =D43*E43 -> 1200
... A46: 39 | B46: Calibration can 200 mm × 250 mm | C46: No. | D46: 1 | E46: 6500 | F46: =D46*E46 -> 6500
B47: CBR Equipment
A48: 40 | B48: CBR mould 152.4 mm dia × 178 mm high | C48: No. | D48: 30 | E48: 18000 | F48: =D48*E48 -> 540000
A49: 41 | B49: Perforated swell plate 150 mm dia | C49: No. | D49: 30 | E49: 4200 | F49: =D49*E49 -> 126000
A50: 42 | B50: Swell tripod | C50: No. | D50: 5 | E50: 4000 | F50: =D50*E50 -> 20000
A51: 43 | B51: Swell dial gauge | C51: No. | D51: 3 | E51: 11000 | F51: =D51*E51 -> 33000
A52: 44 | B52: 2.27 kg slotted surcharge weight | C52: No. | D52: 15 | E52: 3200 | F52: =D52*E52 -> 48000
A53: 45 | B53: 2.27 kg annular surcharge weight | C53: No. | D53: 30 | E53: 3200 | F53: =D53*E53 -> 96000
...

Sheet Survey Equipment
A1: SLOPE STABILISATION AND LAND RECLAMATION OF RUNWAY 06
A2: KISUMU INTERNATIONAL AIRPORT
A3: CONTRACT NO: KAA/KIA/OT/0026/2025-2026
A4: BILL OF QUANTITIES
A5: Bill No. | B5: SURVEY EQUIPMENT
A6: Item No | B6: Description | C6: Units | D6: Quantity | E6: Rate (Ksh) | F6: Amount (Ksh)
A7: 1 | B7: Engineer’s automatic level Wild NAK-2 or similar including tripod | C7: No. | D7: 1 | E7: 60000 | F7: =D7*E7 -> 60000
A8: 2 | B8: Set of tripods (Wild or similar) | C8: No. | D8: 1 | E8: 12000 | F8: =D8*E8 -> 12000
A9: 3 | B9: Survey umbrella | C9: No. | D9: 1 | E9: 4000 | F9: =D9*E9 -> 4000
A10: 4 | B10: 3 m ranging rod (metallic) | C10: No. | D10: 2 | E10: 3000 | F10: =D10*E10 -> 6000
A11: 5 | B11: Levelling staff 5 m with levelling bubble (Wild NLE3 or similar) | C11: No. | D11: 2 | E11: 9000 | F11: =D11*E11 -> 18000
A12: 6 | B12: 30 m steel white face tape | C12: No. | D12: 2 | E12: 3000 | F12: =D12*E12 -> 6000
A13: 7 | B13: 100 m steel band tape | C13: No. | D13: 2 | E13: 8000 | F13: =D13*E13 -> 16000
A14: 8 | B14: 3 m tape measure | C14: No. | D14: 2 | E14: 500 | F14: =D14*E14 -> 1000
A15: 9 | B15: Steel tape repair outfit | C15: No. | D15: 1 | E15: 2000 | F15: =D15*E15 -> 2000
A16: 10 | B16: 2 kg hammer | C16: No. | D16: 2 | E16: 1500 | F16: =D16*E16 -> 3000
A17: 11 | B17: Pangas 16" straight | C17: No. | D17: 5 | E17: 1200 | F17: =D17*E17 -> 6000
A18: 12 | B18: Theodolite equivalent to type WILD T2E | C18: No. | D18: 1 | E18: 220000 | F18: =D18*E18 -> 220000
... A21: 15 | B21: Total station complete with field data collector (TOPCON Model ITS-722 or similar) including accessories and supporting software | C21: No. | D21: 1 | E21: 560000 | F21: =D21*E21 -> 560000
F22: =SUM(F7:F21) -> 944000

Sheet Contractor's Equipment
A1: SLOPE STABILISATION AND LAND RECLAMATION OF RUNWAY 06
A2: KISUMU INTERNATIONAL AIRPORT
A3: CONTRACT NO: KAA/KIA/OT/0026/2025-2026
A4: BILL OF QUANTITIES
A5: Bill No. | B5: CONTRACTOR'S EQUIPMENT
A6: Item No | B6: Description | C6: Units | D6: Quantity | E6: Rate (Ksh) | F6: Amount (Ksh)
A7: 1 | B7: Cat D6 bulldozer or equivalent with Dozer/Ripper attachment | C7: No. | D7: 1 | E7: 18000000 | F7: =D7*E7 -> 18000000
A8: 2 | B8: Cat 140H motor grader or equivalent complete with scarifier | C8: No. | D8: 1 | E8: 12000000 | F8: =D8*E8 -> 12000000
A9: 3 | B9: Vibrating roller (15 tonnes) | C9: No. | D9: 1 | E9: 7000000 | F9: =D9*E9 -> 7000000
A10: 4 | B10: Hand propelled vibrating roller | C10: No. | D10: 1 | E10: 350000 | F10: =D10*E10 -> 350000
A11: 5 | B11: Cat 950C wheel loader or equivalent | C11: No. | D11: 1 | E11: 9000000 | F11: =D11*E11 -> 9000000
A12: 6 | B12: 15 tonne tipper lorry | C12: No. | D12: 6 | E12: 6500000 | F12: =D12*E12 -> 39000000
A13: 7 | B13: 2 cm/hr dewatering pump | C13: No. | D13: 1 | E13: 120000 | F13: =D13*E13 -> 120000
A14: 8 | B14: Concrete mixer 0.3 – 0.7 m³/min | C14: No. | D14: 2 | E14: 350000 | F14: =D14*E14 -> 700000
A15: 9 | B15: Sheep foot roller – 15 tons | C15: No. | D15: 1 | E15: 6000000 | F15: =D15*E15 -> 6000000
A16: 10 | B16: Excavator with loader attachment – 1.7 m³ | C16: No. | D16: 1 | E16: 11000000 | F16: =D16*E16 -> 11000000
A17: 11 | B17: Pick-up truck (1 – 1.5 tonne capacity) | C17: No. | D17: 2 | E17: 4500000 | F17: =D17*E17 -> 9000000
A18: 12 | B18: Compressor with drill (250 c.f.m) complete with tools, hoses and steel bits | C18: No. | D18: 1 | E18: 2200000 | F18: =D18*E18 -> 2200000
... A20: 14 | B20: Self-propelled water tanker (6,000–20,000 litres) with pick-up pump | C20: No. | D20: 2 | E20: 8000000 | F20: =D20*E20 -> 16000000
F21: =SUM(F7:F20) -> 130460000

Sheet Basis of Rates
A1: BASIS OF RATES
A3: Group | B3: Basis | C3: Primary source / note
A4: Road BOQ items | B4: Used Nyanza Region CEM 2025 work item rates for road-related items (site clearance, earthworks, excavation, gravel). | C4: Uploaded file: Nyanza_Region.pdf (Nyanza manual)
A5: Building/structural items | B5: Used Costs Handbook 2025/2026 Western region rates for concrete, waterproofing, blockwork, chainlink/barbed wire materials and related benchmarks. | C5: Uploaded file: Cost Handbook For Construction Works (20252026).pdf
A6: Dayworks plant/labour/materials | B6: Used Nyanza Appendix 1 rates where available; scaled adjacent classes where exact class was not listed. | C6: Uploaded file: Nyanza_Region.pdf Appendix 1
A7: Office and ICT items | B7: Estimated from current Kenya online market prices for desks, chairs, laptops, desktops, printer, refrigerator, extinguishers and internet. | C7: https://neilanfurniture.com/ ; https://ke.microless.com/ ; https://www.jumia.co.ke/ ; https://starlink.com/ke/residential
A8: Survey equipment | B8: Estimated from current Kenya surveying equipment listings for automatic level and total station; related items benchmarked proportionally. | C8: https://geoscopeinstruments.com/
A9: Lab equipment | B9: Specialised items estimated from supplier/quotation benchmarks and adjusted to 2025/26 market levels; small tools benchmarked from local lab supply prices. | C9: https://www.scribd.com/document/479989003/ITHATECH-LTD2 ; https://www.scribd.com/document/736572622/Quote-1662-Edited-3 ; https://www.scribd.com/document/481769892/Proforma-Invoice-2020-0003-AEAL-1-pdf ; https://sciencelab.co.ke/
A10: Geotextile/filter fabric | B10: Estimated from Kenya online retail market per m2 for 300gsm geotextile rolls. | C10: https://www.ebuild.ke/ ; https://www.metrotools.co.ke/
A11: Equipment hire checks | B11: Cross-checked plant assumptions against recent Kenya equipment-hire references. | C11: https://www.constructionkenya.com/8865/equipment-hire-rates-kenya/ ; https://assa.co.ke/
